Программа выведет error.

Вызов функции test() возвращает ссылку на структуру customError. Тип customError имеет метод Error() string, поэтому мы можем присвоить переменной err типа error результат выполнения test. При этом в поле tab переменной err будет передан тип customError и указатель на его метод Error, а в поле data передана ссылка на сам объект, которая как мы видим из "return nil" - будет nil.

Далее мы проверяем через условный оператор if err != nil, который в нашем случае true, т.к. одно из полей err уже не nil и содержит тип customError, соответственно сам err не nil. Поэтому мы попадаем внутрь if и выполняем println("error"), а затем выходим.

Важным нюансом является то, что несмотря на то, что err не nil, одно его поле data, которое ссылается на сам объект, всё еще nil, поэтому при вызове err.Error() мы получим panic: runtime error, т.к. внутри функции будет попытка разыменовать объект e, который nil.